<?xml version="1.0"?>
<robot xmlns:xacro="http://www.ros.org/wiki/xacro" name="robot_assignment_xacro">


<!--To optimize the code it remains to make the progrma to compute the inertia of each link-->
	<xacro:include filename="$(find robot_urdf)/urdf/materials.xacro" />
	<xacro:include filename="$(find robot_urdf)/urdf/robot_assignment.gazebo" />

	<xacro:property name="length_wheel" value="0.04" />
	<xacro:property name="radius_wheel" value="0.08" />
	<xacro:property name="arm_link_length" value="0.15" />
	<xacro:property name="arm_link_radius" value="0.05" />

	<xacro:macro name="default_inertial" params="mass">
			<inertial>
				<mass value="${mass}" />
				<origin rpy="0 1.5707 1.5707" xyz="0 0 0"/>
				<inertia ixx="0.000526666666667" ixy="0" ixz="0" iyy="0.000526666666667" iyz="0" izz="0.001"/>
			</inertial>
	</xacro:macro>
	
	<xacro:macro name="cylinder_inertia" params="mass r l"> 
			<inertia ixx="${mass*(3*r*r+l*l)/12}" ixy = "0" ixz = "0" iyy="${mass*(3*r*r+l*l)/12}" iyz = "0" izz="${mass*(r*r)/2}" /> 
 	</xacro:macro>

	<xacro:macro name="wheel_geometry">
	<geometry>
		<cylinder length="${length_wheel}" radius="${radius_wheel}"/>
	</geometry>
	</xacro:macro>

	<xacro:macro name="arm_link_geometry">
	<geometry>
		<cylinder length="${arm_link_length}" radius="${arm_link_radius}"/>
	</geometry>
	</xacro:macro>
	
	<!--Macro for robot's link-->
	<xacro:macro name="link_wheel" params="name">
		<link name="${name}">
			<inertial>
				<mass value="0.2"/>
				<origin rpy="0 1.5707 1.5707" xyz="0 0 0"/>
				<inertia ixx="0.000526666666667" ixy="0" ixz="0" iyy="0.000526666666667" iyz="0" izz="0.001"/>
			</inertial>
			<collision name="${name}_collision">
				<origin rpy="0 1.5707 1.5707" xyz="0 0 0"/>
				<geometry>
					<cylinder length="0.04" radius="0.1"/>
				</geometry>
			</collision>
			<visual name="${name}_visual">
				<origin rpy="0 1.5707 1.5707" xyz="0 0 0"/>
				<geometry>
					<cylinder length="0.04" radius="0.1"/>
				</geometry>
			</visual>
		</link>
	</xacro:macro>

	<xacro:macro name="arm_base_link" params="name ">
		<link name="${name}">
			<inertial>
				<mass value="0.2"/>
				<origin rpy="0 0 0" xyz="0 0 0"/>
				<inertia ixx="0.000208333333333" ixy="0" ixz="0" iyy="0.000208333333333" iyz="0" izz="0.008333333333333"/>
			</inertial>
			<collision name="arm_base_link_collision">
				<origin rpy="0 0 0" xyz="0 0 0"/>
				<geometry>
					<box size="0.1 0.1 0.05"/>
				</geometry>
			</collision>
			<visual name="arm_base_link_visual">
				<origin rpy="0 0 0" xyz="0 0 0"/>
				<geometry>
					<box size="0.1 0.1 0.05"/>
				</geometry>
			</visual>
		</link>
	</xacro:macro>

	<xacro:macro name="arm_link" params="name ">
		<link name="${name}">
			<inertial>
				<origin xyz="0 0 0" rpy="0 0 0"/>
				<mass value="0.025"/>
				<xacro:cylinder_inertia mass="0.025" r="0.05" l="0.15"/>
			</inertial>
			<collision name="${name}_collision">
				<origin rpy="0 0 0" xyz="0 0 0.075"/>
				<xacro:arm_link_geometry />
			</collision>
			<visual name="${name}_visual">
				<origin rpy="0 0 0" xyz="0 0 0.075"/>
				<xacro:arm_link_geometry />
			</visual>
		</link>
	</xacro:macro>

	<!--Macro for robot's joint-->
	<xacro:macro name="continuous_joint" params="name child parent origin_xyz axis_xyz">
		<joint name="${name}" type="continuous">
			<origin rpy="0 0 0" xyz="${origin_xyz}"/>
			<child link="${child}"/>
			<parent link="${parent}"/>
			<axis rpy="0 0 0" xyz="${axis_xyz}"/>
			<limit effort="10000" velocity="1000"/>
			<joint_properties damping="1.0" friction="1.0"/>
		</joint>
	</xacro:macro>

	<xacro:macro name="revolute_joint" params="name child parent origin_xyz">
		<joint name="${name}" type="revolute">
			<origin rpy="0 0 0" xyz="${origin_xyz}"/>
			<child link="${child}"/>
			<parent link="${parent}"/>
			<axis rpy="0 0 0" xyz="1 0 0"/>
			<limit effort="100.0" upper = "1.5" lower = "-1.5" velocity="0.5"/>
			<joint_properties damping="1.0" friction="1.0"/>
		</joint>
	</xacro:macro>

	<link name="link_chassis">
		<!-- pose and inertial -->
		<pose>0 0 0.1 0 0 0</pose>
		<inertial>
			<mass value="5"/>
			<origin rpy="0 0 0" xyz="0 0 0.1"/>
			<inertia ixx="0.0395416666667" ixy="0" ixz="0" iyy="0.106208333333" iyz="0" izz="0.106208333333"/>
		</inertial>

		<!-- body -->
		<collision name="collision_chassis">
			<geometry>
				<box size="0.5 0.3 0.07"/>
			</geometry>
		</collision>
		<visual>
			<origin rpy="0 0 0" xyz="0 0 0"/>
			<geometry>
				<box size="0.5 0.3 0.07"/>
			</geometry>
			<material name="blue"/>
		</visual>
		<!-- caster front -->
		<collision name="caster_front_collision">
			<origin rpy=" 0 0 0" xyz="0.35 0 -0.05"/>
			<geometry>
				<sphere radius="0.05"/>
			</geometry>
			<surface>
				<friction>
					<ode>
						<mu>0</mu>
						<mu2>0</mu2>
						<slip1>1.0</slip1>
						<slip2>1.0</slip2>
					</ode>
				</friction>
			</surface>
		</collision>
		<visual name="caster_front_visual">
			<origin rpy=" 0 0 0" xyz="0.2 0 -0.05"/>
			<geometry>
				<sphere radius="0.05"/>
			</geometry>
		</visual>
	</link>

	<xacro:link_wheel name="right_wheel_link"/>
	<xacro:link_wheel name="left_wheel_link"/>

	<!-- Here put rìthe arm base link xacro-->
	<xacro:arm_base_link name="arm_base_link"/>
	<xacro:arm_link name="arm_1_link"/>
	<xacro:arm_link name="arm_2_link"/>
	<xacro:arm_link name="arm_3_link"/>

	<link name="camera_link">
	<inertial>
		<mass value="1e-5" />
		<origin xyz="0 0 0" rpy="0 0 0"/>
		<inertia ixx="1e-6" ixy="0" ixz="0" iyy="1e-6" iyz="0" izz="1e-6" />
	</inertial>
	<collision>
		<origin xyz="0 0 0.025" rpy="0 0 0"/>
		<geometry>
			<box size="0.15 0.1 0.05"/>
		</geometry>
	</collision>
	<visual>
		<origin xyz="0 0 0.025" rpy="0 0 0"/>
		<geometry>
			<box size="0.15 0.1 0.05"/>
		</geometry>
		<material name="red">
		<color rgba="1 0 0 1"/>
		</material>
	</visual> 
	</link>
	  
	<!-- ####Definition of all the robot joints#### -->
	<!-- Wheel joints -->

	<xacro:continuous_joint name="right_wheel_joint"   child="right_wheel_link"  parent="link_chassis"  origin_xyz="-0.05 0.15 0"  axis_xyz="0 1 0"/>
	<xacro:continuous_joint name="left_wheel_joint"   child="left_wheel_link"   parent="link_chassis"  origin_xyz="-0.05 -0.15 0"  axis_xyz="0 1 0"/>
	  
	<!-- Arm base link joint -->
	<xacro:continuous_joint name="arm_base_joint"   child="arm_base_link"  parent="link_chassis"  origin_xyz="0 0 0.06"  axis_xyz="0 0 1" />

	<!-- Arm link joints -->
	<xacro:revolute_joint name="base_to_arm_1_joint"   child="arm_1_link"  parent="arm_base_link"  origin_xyz="0 0 0.025"/>
	<xacro:revolute_joint name="arm_1_to_arm_2_joint"   child="arm_2_link"  parent="arm_1_link"  origin_xyz="0 0 0.15"/>
	<xacro:revolute_joint name="arm_2_to_arm_3_joint"   child="arm_3_link"  parent="arm_2_link"  origin_xyz="0 0 0.15"/>
	
	<!--Camera link joint -->
	<joint name="camera_to_arm_3_joint" type="fixed">
		<origin rpy="0 0 0" xyz="0 0 0.15"/>
		<child link="camera_link"/>
		<parent link="arm_3_link"/>
		<axis rpy="0 0 0" xyz="0 1 0"/>
		<limit effort="100.0" upper = "1.5" lower = "-1.5" velocity="0.5"/>
		<joint_properties damping="1.0" friction="1.0"/>
	</joint>

	<!-- Transmissions -->
	<transmission name="arm_base_joint_trans">
		<type>transmission_interface/SimpleTransmission</type>
		<joint name="arm_base_joint">
			<hardwareInterface>hardware_interface/EffortJointInterface</hardwareInterface>
		</joint>
		<actuator name="motor1">
			<hardwareInterface>hardware_interface/EffortJointInterface</hardwareInterface>
			<mechanicalInterface>1</mechanicalInterface>
		</actuator>
	</transmission>

	<transmission name="base_to_arm_1_joint_trans">
		<type>transmission_interface/SimpleTransmission</type>
		<joint name="base_to_arm_1_joint">
			<hardwareInterface>hardware_interface/EffortJointInterface</hardwareInterface>
		</joint>
		<actuator name="motor2">
			<hardwareInterface>hardware_interface/EffortJointInterface</hardwareInterface>
			<mechanicalInterface>1</mechanicalInterface>
		</actuator>
	</transmission>

	<transmission name="arm_1_to_arm_2_joint_trans">
		<type>transmission_interface/SimpleTransmission</type>
		<joint name="arm_1_to_arm_2_joint">
			<hardwareInterface>hardware_interface/EffortJointInterface</hardwareInterface>
		</joint>
		<actuator name="motor3">
			<hardwareInterface>hardware_interface/EffortJointInterface</hardwareInterface>
			<mechanicalInterface>1</mechanicalInterface>
		</actuator>
	</transmission>

	<transmission name="arm_2_to_arm_3_joint_trans">
		<type>transmission_interface/SimpleTransmission</type>
		<joint name="arm_2_to_arm_3_joint">
			<hardwareInterface>hardware_interface/EffortJointInterface</hardwareInterface>
		</joint>
		<actuator name="motor4">
			<hardwareInterface>hardware_interface/EffortJointInterface</hardwareInterface>
			<mechanicalInterface>1</mechanicalInterface>
		</actuator>
	</transmission>

</robot>